<?xml version="1.0" ?>
<!-- =================================================================================== -->
<!-- |    This document was autogenerated by xacro from /home/sanaz/catkin_ws/src/Robotics_Course_ROS_2023/kuka_lbr_iiwa/kuka_lbr_iiwa_description_pkg/urdf/lbr_iiwa_14_r820.xacro | -->
<!-- |    EDITING THIS FILE BY HAND IS NOT RECOMMENDED                                 | -->
<!-- =================================================================================== -->
<robot name="kuka_lbr_iiwa_14_r820">
    <material name="grey">
        <color rgba="0.5 0.5 0.5 1.0" />
    </material>
    <material name="red">
        <color rgba="1.0 0 0 1.0" />
    </material>
    <!-- World -->
    <gazebo reference="world">
        <plugin name="gazebo_ros_control">
            <robotNamespace>/</robotNamespace>
        </plugin>
    </gazebo>
    <gazebo reference="base_link">
        <kp>1000000.0</kp>
        <kd>100.0</kd>
        <mu1>30.0</mu1>
        <mu2>30.0</mu2>
        <maxVel>1.0</maxVel>
        <minDepth>0.001</minDepth>
    </gazebo>
    <gazebo reference="link_1">
        <kp>1000000.0</kp>
        <kd>100.0</kd>
        <mu1>30.0</mu1>
        <mu2>30.0</mu2>
        <maxVel>1.0</maxVel>
        <minDepth>0.001</minDepth>
    </gazebo>
    <gazebo reference="link_2">
        <kp>1000000.0</kp>
        <kd>100.0</kd>
        <mu1>30.0</mu1>
        <mu2>30.0</mu2>
        <maxVel>1.0</maxVel>
        <minDepth>0.001</minDepth>
    </gazebo>
    <gazebo reference="link_3">
        <kp>1000000.0</kp>
        <kd>100.0</kd>
        <mu1>30.0</mu1>
        <mu2>30.0</mu2>
        <maxVel>1.0</maxVel>
        <minDepth>0.001</minDepth>
    </gazebo>
    <gazebo reference="link_4">
        <kp>1000000.0</kp>
        <kd>100.0</kd>
        <mu1>30.0</mu1>
        <mu2>30.0</mu2>
        <maxVel>1.0</maxVel>
        <minDepth>0.001</minDepth>
    </gazebo>
    <gazebo reference="link_5">
        <kp>1000000.0</kp>
        <kd>100.0</kd>
        <mu1>30.0</mu1>
        <mu2>30.0</mu2>
        <maxVel>1.0</maxVel>
        <minDepth>0.001</minDepth>
    </gazebo>
    <gazebo reference="link_6">
        <kp>1000000.0</kp>
        <kd>100.0</kd>
        <mu1>30.0</mu1>
        <mu2>30.0</mu2>
        <maxVel>1.0</maxVel>
        <minDepth>0.001</minDepth>
    </gazebo>
    <gazebo reference="link_7">
        <kp>1000000.0</kp>
        <kd>100.0</kd>
        <mu1>30.0</mu1>
        <mu2>30.0</mu2>
        <maxVel>1.0</maxVel>
        <minDepth>0.001</minDepth>
    </gazebo>
    <gazebo reference="tool0">
        <mu1>10000</mu1>
        <mu2>10000</mu2>
        <kp>1000000.0</kp>
        <kd>100000.0</kd>
        <slip1>0</slip1>
        <slip2>0</slip2>
        <minDepth>0.001</minDepth>
        <maxVel>0</maxVel>
        <torsional>
            <ode>
                <coefficient>1000</coefficient>
                <slip>0</slip>
            </ode>
        </torsional>
        <material>Gazebo/DarkGrey</material>
    </gazebo>
    <gazebo reference="gripper_link">
        <mu1>10000</mu1>
        <mu2>10000</mu2>
        <kp>1000000.0</kp>
        <kd>100000.0</kd>
        <slip1>0</slip1>
        <slip2>0</slip2>
        <minDepth>0.001</minDepth>
        <maxVel>0</maxVel>
        <torsional>
            <ode>
                <coefficient>1000</coefficient>
                <slip>0</slip>
            </ode>
        </torsional>
        <material>Gazebo/DarkGrey</material>
    </gazebo>
    <gazebo reference="gripper_link_sub">
        <mu1>10000</mu1>
        <mu2>10000</mu2>
        <kp>1000000.0</kp>
        <kd>100000.0</kd>
        <slip1>0</slip1>
        <slip2>0</slip2>
        <minDepth>0.001</minDepth>
        <maxVel>0</maxVel>
        <torsional>
            <ode>
                <coefficient>1000</coefficient>
                <slip>0</slip>
            </ode>
        </torsional>
        <material>Gazebo/DarkGrey</material>
    </gazebo>
    <gazebo reference="conveyor_belt">
        <mu1>10000</mu1>
        <mu2>10000</mu2>
        <kp>1000000.0</kp>
        <kd>100000.0</kd>
        <slip1>0</slip1>
        <slip2>0</slip2>
        <minDepth>0.001</minDepth>
        <maxVel>0</maxVel>
        <torsional>
            <ode>
                <coefficient>1000</coefficient>
                <slip>0</slip>
            </ode>
        </torsional>
        <material>Gazebo/DarkGrey</material>
    </gazebo>
    <!-- end effector link -->
    <gazebo reference="end_effector_link">
        <material>Gazebo/RedTransparent</material>
    </gazebo>
    <!-- ros_control plugin -->
    <gazebo>
        <plugin filename="libgazebo_ros_control.so" name="gazebo_ros_control">
            <!--    <robotNamespace>/kuka_lbr_iiwa</robotNamespace>-->
            <controlPeriod>0.001</controlPeriod>
            <robotSimType>gazebo_ros_control/DefaultRobotHWSim</robotSimType>
            <legacyModeNS>true</legacyModeNS>
        </plugin>
    </gazebo>
    <gazebo>
        <!-- loading plugin: mimic joints works in gazebo now -->
        <plugin filename="libroboticsgroup_gazebo_mimic_joint_plugin.so" name="gazebo_gripper_ros_control">
            <joint>gripper</joint>
            <mimicJoint>gripper_sub</mimicJoint>
            <multiplier>1.0</multiplier>
            <offset>0.0</offset>
        </plugin>
    </gazebo>
    <!-- camera -->
    <gazebo reference="camera_link">
        <sensor name="intel_realsense_r200" type="camera">
            <update_rate>30.0</update_rate>
            <camera name="head">
                <horizontal_fov>1.02974</horizontal_fov>
                <image>
                    <width>1920</width>
                    <height>1080</height>
                    <format>R8G8B8</format>
                </image>
                <clip>
                    <near>0.02</near>
                    <far>300</far>
                </clip>
                <noise>
                    <type>gaussian</type>
                    <!-- Noise is sampled independently per pixel on each frame.
               That pixel's noise value is added to each of its color
               channels, which at that point lie in the range [0,1]. -->
                    <mean>0.0</mean>
                    <stddev>0.007</stddev>
                </noise>
            </camera>
            <plugin filename="libgazebo_ros_camera.so" name="camera_controller">
                <alwaysOn>true</alwaysOn>
                <updateRate>0.0</updateRate>
                <cameraName>camera/color</cameraName>
                <imageTopicName>image_raw</imageTopicName>
                <cameraInfoTopicName>camera_info</cameraInfoTopicName>
                <frameName>camera_link</frameName>
                <hackBaseline>0.07</hackBaseline>
                <distortionK1>0.0</distortionK1>
                <distortionK2>0.0</distortionK2>
                <distortionK3>0.0</distortionK3>
                <distortionT1>0.0</distortionT1>
                <distortionT2>0.0</distortionT2>
            </plugin>
        </sensor>
    </gazebo>
    <transmission name="tran1">
        <type>transmission_interface/SimpleTransmission</type>
        <joint name="joint_a1">
            <hardwareInterface>hardware_interface/EffortJointInterface</hardwareInterface>
        </joint>
        <actuator name="motor1">
            <hardwareInterface>hardware_interface/EffortJointInterface</hardwareInterface>
            <mechanicalReduction>1</mechanicalReduction>
        </actuator>
    </transmission>
    <transmission name="tran2">
        <type>transmission_interface/SimpleTransmission</type>
        <joint name="joint_a2">
            <hardwareInterface>hardware_interface/EffortJointInterface</hardwareInterface>
        </joint>
        <actuator name="motor2">
            <hardwareInterface>hardware_interface/EffortJointInterface</hardwareInterface>
            <mechanicalReduction>1</mechanicalReduction>
        </actuator>
    </transmission>
    <transmission name="tran3">
        <type>transmission_interface/SimpleTransmission</type>
        <joint name="joint_a3">
            <hardwareInterface>hardware_interface/EffortJointInterface</hardwareInterface>
        </joint>
        <actuator name="motor3">
            <hardwareInterface>hardware_interface/EffortJointInterface</hardwareInterface>
            <mechanicalReduction>1</mechanicalReduction>
        </actuator>
    </transmission>
    <transmission name="tran4">
        <type>transmission_interface/SimpleTransmission</type>
        <joint name="joint_a4">
            <hardwareInterface>hardware_interface/EffortJointInterface</hardwareInterface>
        </joint>
        <actuator name="motor4">
            <hardwareInterface>hardware_interface/EffortJointInterface</hardwareInterface>
            <mechanicalReduction>1</mechanicalReduction>
        </actuator>
    </transmission>
    <transmission name="tran5">
        <type>transmission_interface/SimpleTransmission</type>
        <joint name="joint_a5">
            <hardwareInterface>hardware_interface/EffortJointInterface</hardwareInterface>
        </joint>
        <actuator name="motor5">
            <hardwareInterface>hardware_interface/EffortJointInterface</hardwareInterface>
            <mechanicalReduction>1</mechanicalReduction>
        </actuator>
    </transmission>
    <transmission name="tran6">
        <type>transmission_interface/SimpleTransmission</type>
        <joint name="joint_a6">
            <hardwareInterface>hardware_interface/EffortJointInterface</hardwareInterface>
        </joint>
        <actuator name="motor6">
            <hardwareInterface>hardware_interface/EffortJointInterface</hardwareInterface>
            <mechanicalReduction>1</mechanicalReduction>
        </actuator>
    </transmission>
    <transmission name="tran7">
        <type>transmission_interface/SimpleTransmission</type>
        <joint name="joint_a7">
            <hardwareInterface>hardware_interface/EffortJointInterface</hardwareInterface>
        </joint>
        <actuator name="motor7">
            <hardwareInterface>hardware_interface/EffortJointInterface</hardwareInterface>
            <mechanicalReduction>1</mechanicalReduction>
        </actuator>
    </transmission>
    <transmission name="tran8">
        <type>transmission_interface/SimpleTransmission</type>
        <joint name="gripper">
            <hardwareInterface>hardware_interface/EffortJointInterface</hardwareInterface>
        </joint>
        <actuator name="motor8">
            <hardwareInterface>hardware_interface/EffortJointInterface</hardwareInterface>
            <mechanicalReduction>1</mechanicalReduction>
        </actuator>
    </transmission>
    <transmission name="tran9">
        <type>transmission_interface/SimpleTransmission</type>
        <joint name="gripper_sub">
            <hardwareInterface>hardware_interface/EffortJointInterface</hardwareInterface>
        </joint>
        <actuator name="motor9">
            <hardwareInterface>hardware_interface/EffortJointInterface</hardwareInterface>
            <mechanicalReduction>1</mechanicalReduction>
        </actuator>
    </transmission>
    <!-- link list -->
    <link name="base_link">
        <visual>
            <origin rpy="0 0 0" xyz="0 0 0" />
            <geometry>
                <mesh filename="package://kuka_lbr_iiwa_description_pkg/meshes/lbr_iiwa_14_r820/visual/base_link.dae" />
            </geometry>
        </visual>
        <collision>
            <origin rpy="0 0 0" xyz="0 0 0" />
            <geometry>
                <mesh filename="package://kuka_lbr_iiwa_description_pkg/meshes/lbr_iiwa_14_r820/collision/base_link.stl" />
            </geometry>
        </collision>
        <inertial>
            <origin xyz="0 0 0" rpy="0 0 0" />
            <mass value="4" />
            <inertia ixx="0.01" ixy="0.0" ixz="0.0" iyy="0.01" iyz="0.0" izz="0.01" />
        </inertial>
    </link>
    <link name="link_1">
        <visual>
            <origin rpy="0 0 0" xyz="0 0 0" />
            <geometry>
                <mesh filename="package://kuka_lbr_iiwa_description_pkg/meshes/lbr_iiwa_14_r820/visual/link_1.dae" />
            </geometry>
        </visual>
        <collision>
            <origin rpy="0 0 0" xyz="0 0 0" />
            <geometry>
                <mesh filename="package://kuka_lbr_iiwa_description_pkg/meshes/lbr_iiwa_14_r820/collision/link_1.stl" />
            </geometry>
        </collision>
        <inertial>
            <origin xyz="0 0 0" rpy="0 0 0" />
            <mass value="3.94781" />
            <inertia ixx="0.00455" ixy="0.0" ixz="0.0" iyy="0.00454" iyz="0.00001" izz="0.00029" />
        </inertial>
    </link>
    <link name="link_2">
        <visual>
            <origin rpy="0 0 0" xyz="0 0 0" />
            <geometry>
                <mesh filename="package://kuka_lbr_iiwa_description_pkg/meshes/lbr_iiwa_14_r820/visual/link_2.dae" />
            </geometry>
        </visual>
        <collision>
            <origin rpy="0 0 0" xyz="0 0 0" />
            <geometry>
                <mesh filename="package://kuka_lbr_iiwa_description_pkg/meshes/lbr_iiwa_14_r820/collision/link_2.stl" />
            </geometry>
        </collision>
        <inertial>
            <origin xyz="0 0 0" rpy="0 0 0" />
            <mass value="4.50275" />
            <inertia ixx="0.00032" ixy="0.0" ixz="0.0" iyy="0.00010" iyz="0.0" izz="0.00042" />
        </inertial>
    </link>
    <link name="link_3">
        <visual>
            <origin rpy="0 0 0" xyz="0 0 0" />
            <geometry>
                <mesh filename="package://kuka_lbr_iiwa_description_pkg/meshes/lbr_iiwa_14_r820/visual/link_3.dae" />
            </geometry>
        </visual>
        <collision>
            <origin rpy="0 0 0" xyz="0 0 0" />
            <geometry>
                <mesh filename="package://kuka_lbr_iiwa_description_pkg/meshes/lbr_iiwa_14_r820/collision/link_3.stl" />
            </geometry>
        </collision>
        <inertial>
            <origin xyz="0 0 0" rpy="0 0 0" />
            <mass value="2.45520" />
            <inertia ixx="0.00223" ixy="-0.00005" ixz="0.00007" iyy="0.00219" iyz="0.00007" izz="0.00073" />
        </inertial>
    </link>
    <link name="link_4">
        <visual>
            <origin rpy="0 0 0" xyz="0 0 0" />
            <geometry>
                <mesh filename="package://kuka_lbr_iiwa_description_pkg/meshes/lbr_iiwa_14_r820/visual/link_4.dae" />
            </geometry>
        </visual>
        <collision>
            <origin rpy="0 0 0" xyz="0 0 0" />
            <geometry>
                <mesh filename="package://kuka_lbr_iiwa_description_pkg/meshes/lbr_iiwa_14_r820/collision/link_4.stl" />
            </geometry>
        </collision>
        <inertial>
            <origin xyz="0 0 0" rpy="0 0 0" />
            <mass value="2.61155" />
            <inertia ixx="0.03844" ixy="0.00088" ixz="-0.00112" iyy="0.01144" iyz="-0.00111" izz="0.04988" />
        </inertial>
    </link>
    <link name="link_5">
        <visual>
            <origin rpy="0 0 0" xyz="0 0 0" />
            <geometry>
                <mesh filename="package://kuka_lbr_iiwa_description_pkg/meshes/lbr_iiwa_14_r820/visual/link_5.dae" />
            </geometry>
        </visual>
        <collision>
            <origin rpy="0 0 0" xyz="0 0 0" />
            <geometry>
                <mesh filename="package://kuka_lbr_iiwa_description_pkg/meshes/lbr_iiwa_14_r820/collision/link_5.stl" />
            </geometry>
        </collision>
        <inertial>
            <origin xyz="0 0 0" rpy="0 0 0" />
            <mass value="3.41000" />
            <inertia ixx="0.00277" ixy="-0.00001" ixz="0.00001" iyy="0.00284" iyz="0.0" izz="0.00012" />
        </inertial>
    </link>
    <link name="link_6">
        <visual>
            <origin rpy="0 0 0" xyz="0 0 0" />
            <geometry>
                <mesh filename="package://kuka_lbr_iiwa_description_pkg/meshes/lbr_iiwa_14_r820/visual/link_6.dae" />
            </geometry>
        </visual>
        <collision>
            <origin rpy="0 0 0" xyz="0 0 0" />
            <geometry>
                <mesh filename="package://kuka_lbr_iiwa_description_pkg/meshes/lbr_iiwa_14_r820/collision/link_6.stl" />
            </geometry>
        </collision>
        <inertial>
            <origin xyz="0 0 0" rpy="0 0 0" />
            <mass value="3.38795" />
            <inertia ixx="0.00050" ixy="-0.00005" ixz="-0.00003" iyy="0.00281" iyz="-0.00004" izz="0.00232" />
        </inertial>
    </link>
    <link name="link_7">
        <visual>
            <origin rpy="0 0 0" xyz="0 0 0" />
            <geometry>
                <mesh filename="package://kuka_lbr_iiwa_description_pkg/meshes/lbr_iiwa_14_r820/visual/link_7.dae" />
            </geometry>
        </visual>
        <collision>
            <origin rpy="0 0 0" xyz="0 0 0" />
            <geometry>
                <mesh filename="package://kuka_lbr_iiwa_description_pkg/meshes/lbr_iiwa_14_r820/collision/link_7.stl" />
            </geometry>
        </collision>
        <inertial>
            <origin xyz="0 0 0" rpy="0 0 0" />
            <mass value="0.35432" />
            <inertia ixx="0.00795" ixy="0.00022" ixz="-0.00029" iyy="0.01089" iyz="-0.00029" izz="0.00294" />
        </inertial>
    </link>
    <link name="tool0">
        <visual>
            <origin rpy="0 0 0" xyz="0 0 0" />
            <geometry>
                <box size="0.05 0.11 0.005" />
            </geometry>
            <material name="grey" />
        </visual>
        <collision>
            <origin rpy="0 0 0" xyz="0 0 0" />
            <geometry>
                <box size="0.05 0.11 0.005" />
            </geometry>
        </collision>
        <inertial>
            <origin xyz="0 0 0" rpy="0 0 0" />
            <mass value="1.0e-03" />
            <inertia ixx="1.0e-03" ixy="0.0" ixz="0.0" iyy="1.0e-03" iyz="0.0" izz="1.0e-03" />
        </inertial>
    </link>
    <!-- end of link list -->
    <!--  Gripper link -->
    <link name="gripper_link">
        <visual>
            <origin rpy="0 0 0" xyz="0.0 0.0 0" />
            <geometry>
                <mesh filename="package://kuka_lbr_iiwa_description_pkg/meshes/gripper/chain_link_grip_l.stl" scale="0.001 0.001 0.001" />
            </geometry>
            <material name="grey" />
        </visual>
        <collision>
            <origin rpy="0 0 0" xyz="0.0 0.0 0" />
            <geometry>
                <mesh filename="package://kuka_lbr_iiwa_description_pkg/meshes/gripper/chain_link_grip_l.stl" scale="0.001 0.001 0.001" />
            </geometry>
        </collision>
        <inertial>
            <origin xyz="0 0 0" rpy="0 0 0" />
            <mass value="1.0e-03" />
            <inertia ixx="1.0e-03" ixy="0.0" ixz="0.0" iyy="1.0e-03" iyz="0.0" izz="1.0e-03" />
        </inertial>
    </link>
    <!--  Gripper link sub -->
    <link name="gripper_link_sub">
        <visual>
            <origin rpy="0 0 0" xyz="0.0 -0.0 0" />
            <geometry>
                <mesh filename="package://kuka_lbr_iiwa_description_pkg/meshes/gripper/chain_link_grip_r.stl" scale="0.001 0.001 0.001" />
            </geometry>
            <material name="grey" />
        </visual>
        <collision>
            <origin rpy="0 0 0" xyz="0.0 -0.0 0" />
            <geometry>
                <mesh filename="package://kuka_lbr_iiwa_description_pkg/meshes/gripper/chain_link_grip_r.stl" scale="0.001 0.001 0.001" />
            </geometry>
        </collision>
        <inertial>
            <origin xyz="0 0 0" rpy="0 0 0" />
            <mass value="1.0e-03" />
            <inertia ixx="1.0e-03" ixy="0.0" ixz="0.0" iyy="1.0e-03" iyz="0.0" izz="1.0e-03" />
        </inertial>
    </link>
    <!-- end effector link -->
    <link name="end_effector_link">
        <visual>
            <origin rpy="0 0 0" xyz="0 0 0" />
            <geometry>
                <box size="0.01 0.01 0.01" />
            </geometry>
            <material name="red" />
        </visual>
        <inertial>
            <origin xyz="0 0 0" />
            <mass value="1.0e-03" />
            <inertia ixx="1.0e-03" ixy="0.0" ixz="0.0" iyy="1.0e-03" iyz="0.0" izz="1.0e-03" />
        </inertial>
    </link>
    <!-- joint list -->
    <joint name="joint_a1" type="revolute">
        <origin rpy="0 0 0" xyz="0 0 0" />
        <parent link="base_link" />
        <child link="link_1" />
        <axis xyz="0 0 1" />
        <limit effort="100" lower="-2.9668" upper="2.9668" velocity="1.4834" />
    </joint>
    <joint name="joint_a2" type="revolute">
        <origin rpy="0 0 0" xyz="-0.00043624 0 0.36" />
        <parent link="link_1" />
        <child link="link_2" />
        <axis xyz="0 1 0" />
        <limit effort="100" lower="-2.0942" upper="2.0942" velocity="1.4834" />
    </joint>
    <joint name="joint_a3" type="revolute">
        <origin rpy="0 0 0" xyz="0 0 0" />
        <parent link="link_2" />
        <child link="link_3" />
        <axis xyz="0 0 1" />
        <limit effort="100" lower="-2.9668" upper="2.9668" velocity="1.7452" />
    </joint>
    <joint name="joint_a4" type="revolute">
        <origin rpy="0 0 0" xyz="0.00043624 0 0.42" />
        <parent link="link_3" />
        <child link="link_4" />
        <axis xyz="0 -1 0" />
        <limit effort="100" lower="-2.0942" upper="2.0942" velocity="1.3089" />
    </joint>
    <joint name="joint_a5" type="revolute">
        <origin rpy="0 0 0" xyz="0 0 0" />
        <parent link="link_4" />
        <child link="link_5" />
        <axis xyz="0 0 1" />
        <limit effort="100" lower="-2.9668" upper="2.9668" velocity="2.2688" />
    </joint>
    <joint name="joint_a6" type="revolute">
        <origin rpy="0 0 0" xyz="0 0 0.4" />
        <parent link="link_5" />
        <child link="link_6" />
        <axis xyz="0 1 0" />
        <limit effort="100" lower="-2.0942" upper="2.0942" velocity="2.356" />
    </joint>
    <joint name="joint_a7" type="revolute">
        <origin rpy="0 0 0" xyz="0 0 0" />
        <parent link="link_6" />
        <child link="link_7" />
        <axis xyz="0 0 1" />
        <limit effort="100" lower="-3.0541" upper="3.0541" velocity="2.356" />
    </joint>
    <joint name="joint_a7-tool0" type="fixed">
        <origin rpy="0 0 0" xyz="0 0 0.126" />
        <parent link="link_7" />
        <child link="tool0" />
        <axis xyz="0 0 0" />
    </joint>
    <!--  Gripper joint  -->
    <joint name="gripper" type="prismatic">
        <parent link="tool0" />
        <child link="gripper_link" />
        <origin rpy="0 -1.57 0" xyz="0 0.017 0" />
        <axis xyz="0 1 0" />
        <limit effort="100" lower="-0.008" upper="0.019" velocity="4.8" />
    </joint>
    <!--  Gripper joint sub -->
    <joint name="gripper_sub" type="prismatic">
        <parent link="tool0" />
        <child link="gripper_link_sub" />
        <origin rpy="0 -1.57 0" xyz="0 -0.017 0" />
        <axis xyz="0 -1 0" />
        <limit effort="100" lower="-0.008" upper="0.019" velocity="4.8" />
        <mimic joint="gripper" multiplier="1" />
    </joint>
    <!-- end effector joint -->
    <joint name="end_effector_joint" type="fixed">
        <origin rpy="0 0 0" xyz="0.0 0.0 0.05" />
        <parent link="tool0" />
        <child link="end_effector_link" />
    </joint>
    <!-- ROS base_link to KUKA $ROBROOT coordinate system transform -->
    <link name="world">
        <collision>
            <origin rpy="0 0 0" xyz="0.0 -0.0 0" />
            <geometry>
                <box size="2 2 0.0001" />
            </geometry>
        </collision>
        <inertial>
            <mass value="0.1" />
            <origin xyz="0 0 0" rpy="0 0 0" />
            <inertia ixx="0.03" iyy="0.03" izz="0.03" ixy="0.0" ixz="0.0" iyz="0.0" />
        </inertial>
    </link>
    <joint name="base_link-world" type="fixed">
        <origin rpy="0 0 0" xyz="0 0 0" />
        <parent link="world" />
        <child link="base_link" />
    </joint>
    <!--  Camera  -->
    <link name="camera_link">
        <visual>
            <origin rpy="0 0 0" xyz="0 0 0" />
            <geometry>
                <box size="0.05 0.05 0.05" />
            </geometry>
            <material name="grey" />
        </visual>
        <collision>
            <origin rpy="0 0 0" xyz="0 0 0" />
            <geometry>
                <box size="0.05 0.05 0.1" />
            </geometry>
        </collision>
        <inertial>
            <mass value="0.2" />
            <origin rpy="0 0 0" xyz="0 0 0" />
            <inertia ixx="1e-6" ixy="0" ixz="0" iyy="1e-6" iyz="0" izz="1e-6" />
        </inertial>
    </link>
    <joint name="camera_link-world" type="fixed">
        <origin rpy="0 1.57 1.57" xyz="0 0 11" />
        <parent link="world" />
        <child link="camera_link" />
    </joint>
</robot>

